<?xml version="1.0"?>
<robot name="wheel" xmlns:xacro="http://www.ros.org/wiki/xacro">

  <xacro:macro name="cylinder_inertia" params="m r h">
    <inertia  ixx="${m*(3*r*r+h*h)/12}" ixy = "0" ixz = "0"
              iyy="${m*(3*r*r+h*h)/12}" iyz = "0"
              izz="${m*r*r/2}" />
  </xacro:macro>

  <xacro:macro name="wheel" params="fb lr parent "> <!--fb : front, back ; lr: left, right -->
    <link name="${fb}_${lr}_wheel">
      <visual>
        <xacro:if value="${mesh_mode == 1}">
          <origin xyz="0 0 ${-wheel_radius}" rpy="0 0 0" />
          <geometry>
            <mesh filename="package://vehicle_description/meshes/wheel.dae" scale=" ${scale_factor} ${scale_factor} ${scale_factor}"/>
          </geometry>
        </xacro:if>
        <xacro:if value="${mesh_mode == 0}">
          <origin xyz="0 0 0" rpy="${pi/2} 0 0" />
          <geometry>
            <cylinder length="${wheel_width}" radius="${wheel_radius}" />
          </geometry>
          <material name="DarkGray" />
        </xacro:if>
      </visual>
      <collision>
        <origin xyz="0 0 0" rpy="${pi/2} 0 0 " />
        <geometry>
          <cylinder length="${wheel_width}" radius="${wheel_radius}" />
        </geometry>
        <!--selfCollide>false</selfCollide-->
      </collision>
      <inertial>
        <mass value="${wheel_mass}" />
        <origin xyz="0 0 0 "  rpy="${pi/2} 0 0" />
        <xacro:cylinder_inertia  m="${wheel_mass}" r="${wheel_radius}" h="${wheel_width}" />
      </inertial>
    </link>

    <gazebo reference="${fb}_${lr}_wheel">
      <mu1 value="1.0"/>
      <mu2 value="1.0"/>
      <kp  value="10000000.0" />
      <kd  value="1.0" />
      <fdir1 value="1 0 0"/>
      <!--material>Gazebo/Grey</material-->
      <turnGravityOff>false</turnGravityOff>
    </gazebo>

    <joint name="${fb}_${lr}_wheel_joint" type="continuous">
      <xacro:if value="${fb == 'front'}">
        <parent link="steer_${lr}"/>
        <origin xyz="0 0 0" rpy="0 0 0" />
      </xacro:if>
      <xacro:if value="${fb == 'rear'}">
        <parent link="${parent}"/>
        <xacro:if value="${lr == 'right'}">
          <origin xyz="${-lb} ${-wheel_base} 0" rpy="0 0 ${pi}" />
        </xacro:if>

        <xacro:if value="${lr == 'left'}">
          <origin xyz="${-lb} ${wheel_base} 0" rpy="0 0 0" />
        </xacro:if>
      </xacro:if>

      <child link="${fb}_${lr}_wheel"/>

      <axis xyz="0 1 0" rpy="0  0" />
      <limit effort="100" velocity="100"/>
      <joint_properties damping="0.0" friction="0.0"/>
    </joint>

    <xacro:if value="${fb == 'front'}">
      <link name="steer_${lr}">
        <inertial>
          <origin xyz="0 0 0" rpy="0 0 0"/>
          <mass value="1.0"/>
          <inertia ixx="0.037227" ixy="0" ixz="0" iyy="0.04" iyz="0" izz="0.06"/>
        </inertial>
      </link>
      <joint name="steer_${lr}_wheel_joint" type="revolute">

        <xacro:if value="${lr == 'right'}">
          <origin xyz="${la} ${-wheel_base} 0" rpy="0 0 ${pi}" />
        </xacro:if>

        <xacro:if value="${lr == 'left'}">
          <origin xyz="${la} ${wheel_base} 0" rpy="0 0 0" />
        </xacro:if>

        <parent link="${parent}"/>
        <child link="steer_${lr}"/>
        <axis xyz="0 0 1"/>
        <limit lower="-0.6" upper="0.6" effort="0" velocity="0"/>
      </joint>
      <!-- Transmission is important to link the joints and the controller -->
      <transmission name="steer_${lr}_wheel_joint_trans">
        <type>transmission_interface/SimpleTransmission</type>
        <joint name="steer_${lr}_wheel_joint">
          <hardwareInterface>hardware_interface/EffortJointInterface</hardwareInterface>
        </joint>
        <actuator name="${lr}_wheel_joint_motor">
          <hardwareInterface>hardware_interface/EffortJointInterface</hardwareInterface>
          <mechanicalReduction>1</mechanicalReduction>
        </actuator>
      </transmission>
    </xacro:if>

    <!-- Transmission is important to link the joints and the controller -->
    <transmission name="${fb}_${lr}_wheel_joint_trans">
      <type>transmission_interface/SimpleTransmission</type>
      <joint name="${fb}_${lr}_wheel_joint">
        <hardwareInterface>hardware_interface/EffortJointInterface</hardwareInterface>
      </joint>
      <actuator name="${fb}_${lr}_wheel_joint_motor">
        <hardwareInterface>hardware_interface/EffortJointInterface</hardwareInterface>
        <mechanicalReduction>1</mechanicalReduction>
      </actuator>
    </transmission>

  </xacro:macro>
</robot>
